2018-09-18 11:51:51,904 :: INFO :: Trying to activate ngrok...
2018-09-18 11:51:51,910 :: INFO :: ...Success => waiting 5 sec
2018-09-18 11:51:56,911 :: INFO :: Getting tunnel
2018-09-18 11:51:56,928 :: ERROR :: test
Traceback (most recent call last):
  File "ngrok.py", line 56, in <module>
    resp = requests.get("http://localhost:404{}/api/tunnels".format(i))
  File "/Library/Frameworks/Python.framework/Versions/2.7/lib/python2.7/site-packages/requests/api.py", line 72, in get
    return request('get', url, params=params, **kwargs)
  File "/Library/Frameworks/Python.framework/Versions/2.7/lib/python2.7/site-packages/requests/api.py", line 58, in request
    return session.request(method=method, url=url, **kwargs)
  File "/Library/Frameworks/Python.framework/Versions/2.7/lib/python2.7/site-packages/requests/sessions.py", line 502, in request
    resp = self.send(prep, **send_kwargs)
  File "/Library/Frameworks/Python.framework/Versions/2.7/lib/python2.7/site-packages/requests/sessions.py", line 612, in send
    r = adapter.send(request, **kwargs)
  File "/Library/Frameworks/Python.framework/Versions/2.7/lib/python2.7/site-packages/requests/adapters.py", line 504, in send
    raise ConnectionError(e, request=request)
ConnectionError: HTTPConnectionPool(host='localhost', port=4040): Max retries exceeded with url: /api/tunnels (Caused by NewConnectionError('<urllib3.connection.HTTPConnection object at 0x105557c10>: Failed to establish a new connection: [Errno 61] Connection refused',))
2018-09-18 11:51:56,932 :: ERROR :: test
Traceback (most recent call last):
  File "ngrok.py", line 56, in <module>
    resp = requests.get("http://localhost:404{}/api/tunnels".format(i))
  File "/Library/Frameworks/Python.framework/Versions/2.7/lib/python2.7/site-packages/requests/api.py", line 72, in get
    return request('get', url, params=params, **kwargs)
  File "/Library/Frameworks/Python.framework/Versions/2.7/lib/python2.7/site-packages/requests/api.py", line 58, in request
    return session.request(method=method, url=url, **kwargs)
  File "/Library/Frameworks/Python.framework/Versions/2.7/lib/python2.7/site-packages/requests/sessions.py", line 502, in request
    resp = self.send(prep, **send_kwargs)
  File "/Library/Frameworks/Python.framework/Versions/2.7/lib/python2.7/site-packages/requests/sessions.py", line 612, in send
    r = adapter.send(request, **kwargs)
  File "/Library/Frameworks/Python.framework/Versions/2.7/lib/python2.7/site-packages/requests/adapters.py", line 504, in send
    raise ConnectionError(e, request=request)
ConnectionError: HTTPConnectionPool(host='localhost', port=4041): Max retries exceeded with url: /api/tunnels (Caused by NewConnectionError('<urllib3.connection.HTTPConnection object at 0x105591f50>: Failed to establish a new connection: [Errno 61] Connection refused',))
2018-09-18 11:51:56,935 :: ERROR :: test
Traceback (most recent call last):
  File "ngrok.py", line 56, in <module>
    resp = requests.get("http://localhost:404{}/api/tunnels".format(i))
  File "/Library/Frameworks/Python.framework/Versions/2.7/lib/python2.7/site-packages/requests/api.py", line 72, in get
    return request('get', url, params=params, **kwargs)
  File "/Library/Frameworks/Python.framework/Versions/2.7/lib/python2.7/site-packages/requests/api.py", line 58, in request
    return session.request(method=method, url=url, **kwargs)
  File "/Library/Frameworks/Python.framework/Versions/2.7/lib/python2.7/site-packages/requests/sessions.py", line 502, in request
    resp = self.send(prep, **send_kwargs)
  File "/Library/Frameworks/Python.framework/Versions/2.7/lib/python2.7/site-packages/requests/sessions.py", line 612, in send
    r = adapter.send(request, **kwargs)
  File "/Library/Frameworks/Python.framework/Versions/2.7/lib/python2.7/site-packages/requests/adapters.py", line 504, in send
    raise ConnectionError(e, request=request)
ConnectionError: HTTPConnectionPool(host='localhost', port=4042): Max retries exceeded with url: /api/tunnels (Caused by NewConnectionError('<urllib3.connection.HTTPConnection object at 0x105591e50>: Failed to establish a new connection: [Errno 61] Connection refused',))
2018-09-18 11:51:56,937 :: ERROR :: test
Traceback (most recent call last):
  File "ngrok.py", line 56, in <module>
    resp = requests.get("http://localhost:404{}/api/tunnels".format(i))
  File "/Library/Frameworks/Python.framework/Versions/2.7/lib/python2.7/site-packages/requests/api.py", line 72, in get
    return request('get', url, params=params, **kwargs)
  File "/Library/Frameworks/Python.framework/Versions/2.7/lib/python2.7/site-packages/requests/api.py", line 58, in request
    return session.request(method=method, url=url, **kwargs)
  File "/Library/Frameworks/Python.framework/Versions/2.7/lib/python2.7/site-packages/requests/sessions.py", line 502, in request
    resp = self.send(prep, **send_kwargs)
  File "/Library/Frameworks/Python.framework/Versions/2.7/lib/python2.7/site-packages/requests/sessions.py", line 612, in send
    r = adapter.send(request, **kwargs)
  File "/Library/Frameworks/Python.framework/Versions/2.7/lib/python2.7/site-packages/requests/adapters.py", line 504, in send
    raise ConnectionError(e, request=request)
ConnectionError: HTTPConnectionPool(host='localhost', port=4043): Max retries exceeded with url: /api/tunnels (Caused by NewConnectionError('<urllib3.connection.HTTPConnection object at 0x105591f10>: Failed to establish a new connection: [Errno 61] Connection refused',))
2018-09-18 11:51:56,939 :: ERROR :: test
Traceback (most recent call last):
  File "ngrok.py", line 56, in <module>
    resp = requests.get("http://localhost:404{}/api/tunnels".format(i))
  File "/Library/Frameworks/Python.framework/Versions/2.7/lib/python2.7/site-packages/requests/api.py", line 72, in get
    return request('get', url, params=params, **kwargs)
  File "/Library/Frameworks/Python.framework/Versions/2.7/lib/python2.7/site-packages/requests/api.py", line 58, in request
    return session.request(method=method, url=url, **kwargs)
  File "/Library/Frameworks/Python.framework/Versions/2.7/lib/python2.7/site-packages/requests/sessions.py", line 502, in request
    resp = self.send(prep, **send_kwargs)
  File "/Library/Frameworks/Python.framework/Versions/2.7/lib/python2.7/site-packages/requests/sessions.py", line 612, in send
    r = adapter.send(request, **kwargs)
  File "/Library/Frameworks/Python.framework/Versions/2.7/lib/python2.7/site-packages/requests/adapters.py", line 504, in send
    raise ConnectionError(e, request=request)
ConnectionError: HTTPConnectionPool(host='localhost', port=4044): Max retries exceeded with url: /api/tunnels (Caused by NewConnectionError('<urllib3.connection.HTTPConnection object at 0x105591f50>: Failed to establish a new connection: [Errno 61] Connection refused',))
2018-09-18 11:51:56,941 :: ERROR :: test
Traceback (most recent call last):
  File "ngrok.py", line 56, in <module>
    resp = requests.get("http://localhost:404{}/api/tunnels".format(i))
  File "/Library/Frameworks/Python.framework/Versions/2.7/lib/python2.7/site-packages/requests/api.py", line 72, in get
    return request('get', url, params=params, **kwargs)
  File "/Library/Frameworks/Python.framework/Versions/2.7/lib/python2.7/site-packages/requests/api.py", line 58, in request
    return session.request(method=method, url=url, **kwargs)
  File "/Library/Frameworks/Python.framework/Versions/2.7/lib/python2.7/site-packages/requests/sessions.py", line 502, in request
    resp = self.send(prep, **send_kwargs)
  File "/Library/Frameworks/Python.framework/Versions/2.7/lib/python2.7/site-packages/requests/sessions.py", line 612, in send
    r = adapter.send(request, **kwargs)
  File "/Library/Frameworks/Python.framework/Versions/2.7/lib/python2.7/site-packages/requests/adapters.py", line 504, in send
    raise ConnectionError(e, request=request)
ConnectionError: HTTPConnectionPool(host='localhost', port=4045): Max retries exceeded with url: /api/tunnels (Caused by NewConnectionError('<urllib3.connection.HTTPConnection object at 0x105591d50>: Failed to establish a new connection: [Errno 61] Connection refused',))
2018-09-18 11:51:56,943 :: ERROR :: test
Traceback (most recent call last):
  File "ngrok.py", line 56, in <module>
    resp = requests.get("http://localhost:404{}/api/tunnels".format(i))
  File "/Library/Frameworks/Python.framework/Versions/2.7/lib/python2.7/site-packages/requests/api.py", line 72, in get
    return request('get', url, params=params, **kwargs)
  File "/Library/Frameworks/Python.framework/Versions/2.7/lib/python2.7/site-packages/requests/api.py", line 58, in request
    return session.request(method=method, url=url, **kwargs)
  File "/Library/Frameworks/Python.framework/Versions/2.7/lib/python2.7/site-packages/requests/sessions.py", line 502, in request
    resp = self.send(prep, **send_kwargs)
  File "/Library/Frameworks/Python.framework/Versions/2.7/lib/python2.7/site-packages/requests/sessions.py", line 612, in send
    r = adapter.send(request, **kwargs)
  File "/Library/Frameworks/Python.framework/Versions/2.7/lib/python2.7/site-packages/requests/adapters.py", line 504, in send
    raise ConnectionError(e, request=request)
ConnectionError: HTTPConnectionPool(host='localhost', port=4046): Max retries exceeded with url: /api/tunnels (Caused by NewConnectionError('<urllib3.connection.HTTPConnection object at 0x105591e90>: Failed to establish a new connection: [Errno 61] Connection refused',))
2018-09-18 11:51:56,946 :: ERROR :: test
Traceback (most recent call last):
  File "ngrok.py", line 56, in <module>
    resp = requests.get("http://localhost:404{}/api/tunnels".format(i))
  File "/Library/Frameworks/Python.framework/Versions/2.7/lib/python2.7/site-packages/requests/api.py", line 72, in get
    return request('get', url, params=params, **kwargs)
  File "/Library/Frameworks/Python.framework/Versions/2.7/lib/python2.7/site-packages/requests/api.py", line 58, in request
    return session.request(method=method, url=url, **kwargs)
  File "/Library/Frameworks/Python.framework/Versions/2.7/lib/python2.7/site-packages/requests/sessions.py", line 502, in request
    resp = self.send(prep, **send_kwargs)
  File "/Library/Frameworks/Python.framework/Versions/2.7/lib/python2.7/site-packages/requests/sessions.py", line 612, in send
    r = adapter.send(request, **kwargs)
  File "/Library/Frameworks/Python.framework/Versions/2.7/lib/python2.7/site-packages/requests/adapters.py", line 504, in send
    raise ConnectionError(e, request=request)
ConnectionError: HTTPConnectionPool(host='localhost', port=4047): Max retries exceeded with url: /api/tunnels (Caused by NewConnectionError('<urllib3.connection.HTTPConnection object at 0x105591e50>: Failed to establish a new connection: [Errno 61] Connection refused',))
2018-09-18 11:51:56,946 :: ERROR :: Error
Traceback (most recent call last):
  File "ngrok.py", line 63, in <module>
    logger.info("Found tunnel {}".format(tunnel))
NameError: name 'tunnel' is not defined
2018-09-18 11:52:25,204 :: INFO :: Trying to activate ngrok...
2018-09-18 11:52:25,209 :: INFO :: ...Success => waiting 5 sec
2018-09-18 11:52:30,213 :: INFO :: Getting tunnel
2018-09-18 11:52:30,232 :: INFO :: Found tunnel http://9dda9436.ngrok.io
2018-09-18 11:52:30,232 :: INFO :: Running main code
2018-09-18 11:52:30,232 :: INFO :: Done, sleeping 2 sec
2018-09-18 11:52:32,237 :: INFO :: Registering to server
2018-09-18 11:52:32,237 :: INFO :: Getting IP address
2018-09-18 11:52:32,238 :: INFO :: Getting mac
2018-09-18 11:52:32,825 :: INFO :: Done!
2018-09-18 11:52:57,725 :: INFO :: Trying to activate ngrok...
2018-09-18 11:52:57,729 :: INFO :: ...Success => waiting 5 sec
2018-09-18 11:53:01,309 :: ERROR :: Error
Traceback (most recent call last):
  File "ngrok.py", line 54, in <module>
    time.sleep(5)
KeyboardInterrupt
2018-09-18 11:53:21,325 :: ERROR :: Error
Traceback (most recent call last):
  File "ngrok.py", line 51, in <module>
    time.sleep(2)
KeyboardInterrupt
2018-09-18 11:53:28,372 :: INFO :: Trying to activate ngrok...
2018-09-18 11:53:28,375 :: INFO :: ...Success => waiting 5 sec
2018-09-18 11:53:33,381 :: INFO :: Getting tunnel
2018-09-18 11:53:33,396 :: INFO :: Found tunnel http://37312a01.ngrok.io
2018-09-18 11:53:33,396 :: INFO :: Running main code
2018-09-18 11:53:33,396 :: INFO :: Done, sleeping 2 sec
2018-09-18 11:53:33,695 :: ERROR :: Error
Traceback (most recent call last):
  File "ngrok.py", line 69, in <module>
    time.sleep(2)
KeyboardInterrupt
2018-09-18 11:53:40,524 :: INFO :: Trying to activate ngrok...
2018-09-18 11:53:40,529 :: INFO :: ...Success => waiting 5 sec
2018-09-18 11:53:45,531 :: INFO :: Getting tunnel
2018-09-18 11:53:45,545 :: INFO :: Found tunnel http://6c9faa79.ngrok.io
2018-09-18 11:53:45,545 :: INFO :: Running main code
2018-09-18 11:53:45,545 :: INFO :: Done, sleeping 2 sec
2018-09-18 11:53:47,549 :: INFO :: Registering to server
2018-09-18 11:53:47,549 :: INFO :: Getting IP address
2018-09-18 11:53:47,549 :: INFO :: Getting mac
2018-09-18 11:53:47,937 :: INFO :: Done!
2018-09-18 11:54:26,782 :: INFO :: Trying to activate ngrok...
2018-09-18 11:54:26,786 :: INFO :: ...Success => waiting 5 sec
2018-09-18 11:54:31,788 :: INFO :: Getting tunnel
2018-09-18 11:54:31,803 :: INFO :: Found tunnel http://e906afe2.ngrok.io
2018-09-18 11:54:31,803 :: INFO :: Running main code
2018-09-18 11:54:31,803 :: INFO :: Done, sleeping 2 sec
2018-09-18 11:54:33,804 :: INFO :: Registering to server
2018-09-18 11:54:33,804 :: INFO :: Getting IP address
2018-09-18 11:54:33,804 :: INFO :: Getting mac
2018-09-18 11:54:34,292 :: INFO :: Done!
